#VRML_SIM R2023b utf8

EXTERNPROTO "https://raw.githubusercontent.com/cyberbotics/webots/R2022b/projects/objects/backgrounds/protos/TexturedBackground.proto"
EXTERNPROTO "https://raw.githubusercontent.com/cyberbotics/webots/R2022b/projects/objects/backgrounds/protos/TexturedBackgroundLight.proto"

WorldInfo {
  info [
    "A simple RCJ Soccer game simulated using Webots."
  ]
  title "RCJ Soccer Sim"
  optimalThreadCount 8
}
Viewpoint {
  orientation -0.013516517695185797 0.9997742190862663 0.016395566469082745 0.8262322422748571
  position -1.4356754066767554 0.45429436008314766 1.403686220611954
}
TexturedBackground {
}
TexturedBackgroundLight {
}
DEF SOCCER_FIELD Solid {
  children [
    Solid {
      translation 0 -1.175 0.05
      rotation 0 0 1 1.5708
      children [
        Shape {
          appearance PBRAppearance {
            baseColor 0.466667 0.462745 0.482353
            metalness 0
          }
          geometry DEF WALL_SHAPE Box {
            size 0.05 1.2 0.1
          }
        }
      ]
      name "west_wall"
      boundingObject USE WALL_SHAPE
    }
    Solid {
      translation 0 1.175 0.05
      rotation 0 0 1 1.5708
      children [
        Shape {
          appearance PBRAppearance {
            baseColor 0.466667 0.462745 0.482353
            metalness 0
          }
          geometry DEF WALL_SHAPE Box {
            size 0.05 1.2 0.1
          }
        }
      ]
      name "east_wall"
      boundingObject USE WALL_SHAPE
    }
    Solid {
      translation -0.575 0 0.05
      children [
        Shape {
          appearance PBRAppearance {
            baseColor 0.466667 0.462745 0.482353
            metalness 0
          }
          geometry DEF WALL_SHAPE Box {
            size 0.05 2.3 0.1
          }
        }
      ]
      name "north_wall"
      boundingObject USE WALL_SHAPE
    }
    Solid {
      translation 0.575 0 0.05
      children [
        Shape {
          appearance PBRAppearance {
            baseColor 0.466667 0.462745 0.482353
            metalness 0
          }
          geometry DEF WALL_SHAPE Box {
            size 0.05 2.3 0.1
          }
        }
      ]
      name "south_wall"
      boundingObject USE WALL_SHAPE
    }
    DEF GROUND Pose {
      rotation 0 0 1 1.5707996938995747
      children [
        DEF GROUND_SHAPE Shape {
          appearance PBRAppearance {
            baseColorMap ImageTexture {
              url [
                "textures/field2.png"
              ]
            }
            metalness 0
          }
          geometry Plane {
            size 2.3 1.1
          }
        }
      ]
    }
    DEF PURPLE_GOAL Shape {
      appearance PBRAppearance {
        baseColor 0.466667 0.462745 0.482353
        roughness 1
        metalness 0
      }
      geometry IndexedFaceSet {
        coord Coordinate {
          point [
            -0.21 -1.16 0
            0.21 -1.16 0
            0.21 -0.95 0
            0.2 -0.95 0
            0.2 -1.15 0
            -0.2 -1.15 0
            -0.2 -0.95 0
            -0.21 -0.95 0
            -0.21 -1.16 0
            -0.21 -1.16 0.12
            0.21 -1.16 0.12
            0.21 -0.95 0.12
            0.2 -0.95 0.12
            0.2 -1.15 0.12
            -0.2 -1.15 0.12
            -0.2 -0.95 0.12
            -0.21 -0.95 0.12
            -0.21 -1.16 0.12
          ]
        }
        coordIndex [
          0, 1, 2, 3, 4, 5, 6, 7, 8, -1, 0, 1, 10, 9, -1, 1, 2, 11, 10, -1, 2, 3, 12, 11, -1, 3, 4, 13, 12, -1, 4, 5, 14, 13, -1, 5, 6, 15, 14, -1, 6, 7, 16, 15, -1, 7, 8, 17, 16, -1
        ]
      }
    }
    DEF BLUE_GOAL Shape {
      appearance PBRAppearance {
        baseColor 0.368627 0.360784 0.392157
        roughness 1
        metalness 0
      }
      geometry IndexedFaceSet {
        coord Coordinate {
          point [
            -0.21 1.16 0
            -0.21 0.95 0
            -0.2 0.95 0
            -0.2 1.15 0
            0.2 1.15 0
            0.2 0.95 0
            0.21 0.95 0
            0.21 1.16 0
            -0.21 1.16 0
            -0.21 1.16 0.12
            -0.21 0.95 0.12
            -0.2 1.15 0.12
            -0.2 1.15 0.12
            0.2 1.15 0.12
            0.2 0.95 0.12
            0.21 0.95 0.12
            0.21 1.16 0.12
            -0.21 1.16 0.12
          ]
        }
        coordIndex [
          0, 1, 2, 3, 4, 5, 6, 7, 8, -1, 0, 1, 10, 9, -1, 1, 2, 11, 10, -1, 2, 3, 12, 11, -1, 3, 4, 13, 12, -1, 4, 5, 14, 13, -1, 5, 6, 15, 14, -1, 6, 7, 16, 15, -1, 7, 8, 17, 16, -1
        ]
      }
    }
  ]
  name "soccer field"
  boundingObject Group {
    children [
      USE PURPLE_GOAL
      USE BLUE_GOAL
      USE GROUND
    ]
  }
  locked TRUE
}
DEF BALL Robot {
  translation -0.2 0 0.0208079
  rotation 0.7071067811865474 0.7071067811865475 0 -2.62318
  children [
    DEF FOOTBALL_SHAPE Shape {
      appearance PBRAppearance {
        baseColor 0.964706 0.827451 0.176471
        roughness 0.4
        metalness 0
      }
      geometry Sphere {
        radius 0.021
        subdivision 3
      }
    }
    Emitter {
      name "ball emitter"
      type "infra-red"
      range 0.6
      channel 4
      baudRate 115200
      allowedChannels [
        4
      ]
    }
  ]
  name "soccer ball"
  model "soccer ball"
  boundingObject USE FOOTBALL_SHAPE
  physics Physics {
    density -1
    mass 0.05
  }
  recognitionColors [
    1 1 1
    0 0 0
  ]
  controller "<none>"
  synchronization FALSE
}
DEF A Robot {
  translation 0 0.9 0.045
  rotation 0 0 -0.9999999999988647 1.5708
  children [
    DEF A_ROBOT_BODY Solid {
      children [
        DEF A_ROBOT_BODY_GROUP Group {
          children [
            Shape {
              appearance PBRAppearance {
                baseColor 0.466667 0.462745 0.482353
                roughness 1
                metalness 0
              }
              geometry Box {
                size 0.1 0.08 0.075
              }
            }
            Pose {
              translation 0.065 0.042 -0.02
              rotation 0 0 1 -1.3
              children [
                Shape {
                  appearance PBRAppearance {
                    baseColor 0.141176 0.121569 0.192157
                  }
                  geometry Box {
                    size 0.005 0.04 0.03
                  }
                }
              ]
            }
            Pose {
              translation 0.065 -0.042 -0.02
              rotation 0 0 1 1.3
              children [
                Shape {
                  appearance PBRAppearance {
                    baseColor 0.141176 0.121569 0.192157
                  }
                  geometry Box {
                    size 0.005 0.04 0.03
                  }
                }
              ]
            }
          ]
        }
      ]
    }
    BallJoint {
      jointParameters BallJointParameters {
        anchor 0.04 0 -0.041
      }
      jointParameters2 JointParameters {
      }
      jointParameters3 JointParameters {
        axis 0 1 0
      }
      endPoint Solid {
        translation 0.04 -3.043260000005924e-06 -0.040999999999999995
        rotation -0.7292438803291519 0.6752034868553416 -0.11092165857428475 6.283185307179586
        children [
          DEF BALL_WHEEL Shape {
            appearance PBRAppearance {
              baseColor 0.239216 0.219608 0.27451
              metalness 0
            }
            geometry Sphere {
              radius 0.004
            }
          }
        ]
        name "Ball"
        contactMaterial "wheel"
        boundingObject USE BALL_WHEEL
        physics Physics {
          density -1
          mass 0.028
        }
      }
    }
    DEF ROOF Pose {
      translation 0 0 0.038
      children [
        Shape {
          appearance PBRAppearance {
            baseColorMap ImageTexture {
              url [
                "textures/TeamBlue2.png"
              ]
            }
            metalness 0
          }
          geometry Box {
            size 0.1 0.08 0.001
          }
        }
      ]
    }
    HingeJoint {
      jointParameters HingeJointParameters {
        position -7.771629997904354e-09
        axis 0 1 0
        anchor -0.015 -0.045 -0.025
      }
      device [
        RotationalMotor {
          name "left wheel motor"
        }
        PositionSensor {
          name "left wheel sensor"
        }
      ]
      endPoint Solid {
        translation -0.014999999961141848 -0.045 -0.025
        rotation -3.394145216646228e-10 -3.39416655731429e-10 1 1.5707999999999953
        children [
          Pose {
            rotation -0.5771969549958951 0.5776567755050862 -0.5771969549958951 2.0939354039397986
            children [
              DEF WHEEL_SHAPE Shape {
                appearance PBRAppearance {
                  roughness 1
                  metalness 0
                }
                geometry Cylinder {
                  height 0.01
                  radius 0.02
                }
              }
            ]
          }
        ]
        name "right wheel"
        boundingObject Pose {
          rotation -0.5771969549958951 0.5776567755050862 -0.5771969549958951 2.0939354039397986
          children [
            USE WHEEL_SHAPE
          ]
        }
        physics DEF WHEEL_PHYSICS Physics {
          density -1
          mass 0.005
        }
      }
    }
    HingeJoint {
      jointParameters HingeJointParameters {
        position -7.74663356251063e-09
        axis 0 1 0
        anchor -0.015 0.045 -0.025
      }
      device [
        RotationalMotor {
          name "right wheel motor"
        }
        PositionSensor {
          name "right wheel sensor"
        }
      ]
      endPoint Solid {
        translation -0.014999999961266825 0.045 -0.025
        rotation -1.2706550521589524e-10 -1.270619624182062e-10 1 1.570799693899568
        children [
          Pose {
            rotation -0.5771969549958951 0.5776567755050862 -0.5771969549958951 2.0939354039397986
            children [
              Shape {
                appearance PBRAppearance {
                  roughness 1
                  metalness 0
                }
                geometry Cylinder {
                  height 0.01
                  radius 0.02
                }
              }
            ]
          }
        ]
        name "left wheel"
        boundingObject Pose {
          rotation -0.5771969549958951 0.5776567755050862 -0.5771969549958951 2.0939354039397986
          children [
            Shape {
              appearance PBRAppearance {
                roughness 1
                metalness 0
              }
              geometry Cylinder {
                height 0.01
                radius 0.02
              }
            }
          ]
        }
        physics USE WHEEL_PHYSICS
      }
    }
  ]
  name "A Robot"
  boundingObject USE A_ROBOT_BODY_GROUP
  physics DEF ROBOT_PHYSICS Physics {
    density -1
    mass 0.2
  }
  controller "blue_robot"
  synchronization FALSE
}
DEF B Robot {
  translation 0 -0.9 0.045
  rotation 0 0 -0.9999999999988647 -1.5708
  children [
    BallJoint {
      jointParameters BallJointParameters {
        anchor 0.04 0 -0.041
      }
      jointParameters2 JointParameters {
      }
      jointParameters3 JointParameters {
        axis 0 1 0
      }
      endPoint Solid {
        translation 0.04 -3.043260000007584e-06 -0.041
        rotation -0.9706705053879372 0.19233099797160363 -0.1442482484787027 6.283185307179586
        children [
          DEF BALL_WHEEL Shape {
            appearance PBRAppearance {
              baseColor 0.239216 0.219608 0.27451
              metalness 0
            }
            geometry Sphere {
              radius 0.004
            }
          }
        ]
        name "solid(1)"
        contactMaterial "wheel"
        boundingObject USE BALL_WHEEL
        physics Physics {
          density -1
          mass 0.028
        }
      }
    }
    Pose {
      translation 0 0 0.038
      children [
        Shape {
          appearance PBRAppearance {
            baseColorMap ImageTexture {
              url [
                "textures/TeamPurple2.png"
              ]
            }
            metalness 0
          }
          geometry Box {
            size 0.1 0.08 0.001
          }
        }
      ]
    }
    HingeJoint {
      jointParameters HingeJointParameters {
        position -7.771629997904354e-09
        axis 0 1 0
        anchor -0.015 -0.045 -0.025
      }
      device [
        RotationalMotor {
          name "left wheel motor"
        }
        PositionSensor {
          name "left wheel sensor"
        }
      ]
      endPoint Solid {
        translation -0.014999999961141848 -0.045 -0.025
        rotation -3.394151497004564e-10 -3.3941669498366144e-10 1 1.5707999999999982
        children [
          Pose {
            rotation -0.5771969549958951 0.5776567755050862 -0.5771969549958951 2.0939354039397986
            children [
              DEF WHEEL_SHAPE Shape {
                appearance PBRAppearance {
                  roughness 1
                  metalness 0
                }
                geometry Cylinder {
                  height 0.01
                  radius 0.02
                }
              }
            ]
          }
        ]
        name "right wheel"
        boundingObject Pose {
          rotation -0.5771969549958951 0.5776567755050862 -0.5771969549958951 2.0939354039397986
          children [
            USE WHEEL_SHAPE
          ]
        }
        physics DEF WHEEL_PHYSICS Physics {
          density -1
          mass 0.005
        }
      }
    }
    HingeJoint {
      jointParameters HingeJointParameters {
        position -7.74663356251063e-09
        axis 0 1 0
        anchor -0.015 0.045 -0.025
      }
      device [
        RotationalMotor {
          name "right wheel motor"
        }
        PositionSensor {
          name "right wheel sensor"
        }
      ]
      endPoint Solid {
        translation -0.01499999996126683 0.045 -0.025
        rotation -1.2706546596365383e-10 -1.2706103999043544e-10 1 1.5707996938995703
        children [
          Pose {
            rotation -0.5771969549958951 0.5776567755050862 -0.5771969549958951 2.0939354039397986
            children [
              Shape {
                appearance PBRAppearance {
                  roughness 1
                  metalness 0
                }
                geometry Cylinder {
                  height 0.01
                  radius 0.02
                }
              }
            ]
          }
        ]
        name "left wheel"
        boundingObject Pose {
          rotation -0.5771969549958951 0.5776567755050862 -0.5771969549958951 2.0939354039397986
          children [
            Shape {
              appearance PBRAppearance {
                roughness 1
                metalness 0
              }
              geometry Cylinder {
                height 0.01
                radius 0.02
              }
            }
          ]
        }
        physics USE WHEEL_PHYSICS
      }
    }
    DEF PURPLE_ROBOT_SHAPE Shape {
      appearance PBRAppearance {
        baseColor 0.505882 0 0.498039
        roughness 1
        metalness 0
      }
      geometry Box {
        size 0.1 0.08 0.075
      }
    }
  ]
  name "B Robot"
  boundingObject USE PURPLE_ROBOT_SHAPE
  physics DEF ROBOT_PHYSICS Physics {
    density -1
    mass 0.2
  }
  controller "<none>"
  synchronization FALSE
}
Robot {
  children [
    Camera {
      translation 0 0 1.2
      rotation 0 1 0 1.57
      fieldOfView 1.54
      width 1280
      height 720
    }
  ]
  name "supervisor"
  controller "referee_supervisor"
  supervisor TRUE
}
